Workbook

Sheet 059M - Mano de obra PIMS
A1: CD_EMPRESA_ERP | B1: CD_FILIAL_ERP | C1: DT_REFER | D1: CD_FUNC_ERP | E1: QT_HORAS | F1: VL_TOTAL | G1: DT_ENVIO_ERP | H1: DT_INTEG_PIMS | I1: FG_STATUS_INTEG | J1: Bono cierre pliego | K1: VL_TOTAL1 | L1: B.cierre | M1: VL_TOTAL2
A2: 1000 | B2: 1000 | C2: 45961 | D2: 91391 | E2: 240 | F2: 4419.29 | G2: 45965 | I2: NI | J2: =IFERROR(VLOOKUP(D2,'INf. RRHH'!$A:$B,2,0),0) -> 2900 | K2: =+F2-J2 -> 1519.29 | L2: =ROUND(J2/3,2) -> 966.67 | M2: =+K2+L2 -> 2485.96
A3: 1000 | B3: 1000 | C3: 45961 | D3: 91588 | E3: 290.5 | F3: 6675.05 | G3: 45965 | I3: NI | J3: =IFERROR(VLOOKUP(D3,'INf. RRHH'!$A:$B,2,0),0) -> 2900 | K3: =+F3-J3 -> 3775.05 | L3: =ROUND(J3/3,2) -> 966.67 | M3: =+K3+L3 -> 4741.72
A4: 1000 | B4: 1000 | C4: 45961 | D4: 91658 | E4: 402 | F4: 6826.27 | G4: 45965 | I4: NI | J4: =IFERROR(VLOOKUP(D4,'INf. RRHH'!$A:$B,2,0),0) -> 2900 | K4: =+F4-J4 -> 3926.27 | L4: =ROUND(J4/3,2) -> 966.67 | M4: =+K4+L4 -> 4892.94
A5: 1000 | B5: 1000 | C5: 45961 | D5: 91699 | E5: 392 | F5: 7000.89 | G5: 45965 | I5: NI | J5: =IFERROR(VLOOKUP(D5,'INf. RRHH'!$A:$B,2,0),0) -> 2900 | K5: =+F5-J5 -> 4100.89 | L5: =ROUND(J5/3,2) -> 966.67 | M5: =+K5+L5 -> 5067.56
A6: 1000 | B6: 1000 | C6: 45961 | D6: 92145 | E6: 192 | F6: 4686.78 | G6: 45965 | I6: NI | J6: =IFERROR(VLOOKUP(D6,'INf. RRHH'!$A:$B,2,0),0) -> 2900 | K6: =+F6-J6 -> 1786.78 | L6: =ROUND(J6/3,2) -> 966.67 | M6: =+K6+L6 -> 2753.45
A7: 1000 | B7: 1000 | C7: 45961 | D7: 92364 | E7: 257 | F7: 6420.51 | G7: 45965 | I7: NI | J7: =IFERROR(VLOOKUP(D7,'INf. RRHH'!$A:$B,2,0),0) -> 2900 | K7: =+F7-J7 -> 3520.51 | L7: =ROUND(J7/3,2) -> 966.67 | M7: =+K7+L7 -> 4487.18
A8: 1000 | B8: 1000 | C8: 45961 | D8: 92471 | E8: 240 | F8: 4429.5 | G8: 45965 | I8: NI | J8: =IFERROR(VLOOKUP(D8,'INf. RRHH'!$A:$B,2,0),0) -> 2900 | K8: =+F8-J8 -> 1529.5 | L8: =ROUND(J8/3,2) -> 966.67 | M8: =+K8+L8 -> 2496.17
A9: 1000 | B9: 1000 | C9: 45961 | D9: 92489 | E9: 255 | F9: 4162.09 | G9: 45965 | I9: NI | J9: =IFERROR(VLOOKUP(D9,'INf. RRHH'!$A:$B,2,0),0) -> 2900 | K9: =+F9-J9 -> 1262.09 | L9: =ROUND(J9/3,2) -> 966.67 | M9: =+K9+L9 -> 2228.76
A10: 1000 | B10: 1000 | C10: 45961 | D10: 92597 | E10: 311.5 | F10: 6992.51 | G10: 45965 | I10: NI | J10: =IFERROR(VLOOKUP(D10,'INf. RRHH'!$A:$B,2,0),0) -> 2900 | K10: =+F10-J10 -> 4092.51 | L10: =ROUND(J10/3,2) -> 966.67 | M10: =+K10+L10 -> 5059.18
A11: 1000 | B11: 1000 | C11: 45961 | D11: 92696 | E11: 251 | F11: 6307.75 | G11: 45965 | I11: NI | J11: =IFERROR(VLOOKUP(D11,'INf. RRHH'!$A:$B,2,0),0) -> 2900 | K11: =+F11-J11 -> 3407.75 | L11: =ROUND(J11/3,2) -> 966.67 | M11: =+K11+L11 -> 4374.42
A12: 1000 | B12: 1000 | C12: 45961 | D12: 92722 | E12: 72 | F12: 3776.22 | G12: 45965 | I12: NI | J12: =IFERROR(VLOOKUP(D12,'INf. RRHH'!$A:$B,2,0),0) -> 2900 | K12: =+F12-J12 -> 876.22 | L12: =ROUND(J12/3,2) -> 966.67 | M12: =+K12+L12 -> 1842.89
A13: 1000 | B13: 1000 | C13: 45961 | D13: 92749 | E13: 275.5 | F13: 5953.77 | G13: 45965 | I13: NI | J13: =IFERROR(VLOOKUP(D13,'INf. RRHH'!$A:$B,2,0),0) -> 2900 | K13: =+F13-J13 -> 3053.77 | L13: =ROUND(J13/3,2) -> 966.67 | M13: =+K13+L13 -> 4020.44
... A1273: 1000 | B1273: 1000 | C1273: 45961 | D1273: 91175 | E1273: 240 | F1273: 5154.05 | G1273: 45965 | I1273: NI | J1273: =IFERROR(VLOOKUP(D1273,'INf. RRHH'!$A:$B,2,0),0) -> 2900 | K1273: =+F1273-J1273 -> 2254.05 | L1273: =ROUND(J1273/3,2) -> 966.67 | M1273: =+K1273+L1273 -> 3220.72
D1274: Tabla intermedia | F1274: =SUM(F2:F1273) -> 7446174.5 | J1274: =SUM(J2:J1273) -> 3506100 | K1274: =SUM(K2:K1273) -> 3940074.5 | L1274: =SUM(L2:L1273) -> 1168703.9 | M1274: =SUM(M2:M1273) -> 5108778.4
D1275: SAP | F1275: =+SAP!O899 -> 7446174.5 | M1275: =+'SAP (1)'!R899 -> 5108778.4
D1276: Diferencia | F1276: =+F1275-F1274 -> 0 | L1276: =SUM('SAP (1)'!R530:R594) -> 1168703.9 | M1276: =+M1275-M1274 -> 8.3819032e-09
L1277: =+L1276-L1274 -> -1.094304e-08

Sheet SAP
A1: Sociedad | B1: Cuenta de mayor | C1: Cuenta de mayor: Texto breve | D1: Área funcional | E1: Centro de coste | F1: Centro de coste: Texto explicativo | G1: Clase de documento | H1: Fecha de documento | I1: Fe.contabilización | J1: Fecha de entrada | K1: Clave de referencia | L1: Nº documento | M1: Referencia | N1: Texto cab.documento | O1: Valor de moneda de documento | P1: Clave de moneda de documento | Q1: Valor de moneda de sociedad | R1: Clave de moneda de sociedad | S1: Valor de moneda fuerte | T1: Moneda fuerte | U1: Nombre 2 | V1: Anulado | W1: Anulado con | X1: Documento anulación
A2: 1000 | B2: 6211100001 | C2: Sueldos - Rem básica | D2: AF01 | E2: 1020230308 | F2: Labores de campo cosecha | G2: PL | H2: 45961 | I2: 45961 | J2: 45964 | K2: 0000002436 | L2: 5500000425 | M2: HRPAY00001 | N2: PP0000002374 | O2: 472.03 | P2: PEN | Q2: 472.03 | R2: PEN | S2: 138.91 | T2: USD
A3: 1000 | B3: 6211100001 | C3: Sueldos - Rem básica | D3: AF01 | E3: 1020231210 | F3: Ord - Virú | G3: PL | H3: 45961 | I3: 45961 | J3: 45964 | K3: 0000002436 | L3: 5500000425 | M3: HRPAY00001 | N3: PP0000002374 | O3: 4285.25 | P3: PEN | Q3: 4285.25 | R3: PEN | S3: 1261.11 | T3: USD
A4: 1000 | B4: 6211100001 | C4: Sueldos - Rem básica | D4: AF01 | E4: 1020231212 | F4: Ord - Zona II | G4: PL | H4: 45961 | I4: 45961 | J4: 45964 | K4: 0000002436 | L4: 5500000425 | M4: HRPAY00001 | N4: PP0000002374 | O4: 3720.03 | P4: PEN | Q4: 3720.03 | R4: PEN | S4: 1094.77 | T4: USD
A5: 1000 | B5: 6211100001 | C5: Sueldos - Rem básica | D5: AF01 | E5: 1020231601 | F5: Oficina control técnico agronómico | G5: PL | H5: 45961 | I5: 45961 | J5: 45964 | K5: 0000002436 | L5: 5500000425 | M5: HRPAY00001 | N5: PP0000002374 | O5: 1640 | P5: PEN | Q5: 1640 | R5: PEN | S5: 482.64 | T5: USD
A6: 1000 | B6: 6211100001 | C6: Sueldos - Rem básica | D6: AF01 | E6: 1020230303 | F6: Aco - Corte de caña | G6: PL | H6: 45961 | I6: 45961 | J6: 45964 | K6: 0000002436 | L6: 5500000425 | M6: HRPAY00001 | N6: PP0000002374 | O6: 728.66 | P6: PEN | Q6: 728.66 | R6: PEN | S6: 214.44 | T6: USD
A7: 1000 | B7: 6211100001 | C7: Sueldos - Rem básica | D7: AF01 | E7: 1020230301 | F7: Aco - Administración de cosecha | G7: PL | H7: 45961 | I7: 45961 | J7: 45964 | K7: 0000002436 | L7: 5500000425 | M7: HRPAY00001 | N7: PP0000002374 | O7: 18824.03 | P7: PEN | Q7: 18824.03 | R7: PEN | S7: 5539.74 | T7: USD
A8: 1000 | B8: 6211100001 | C8: Sueldos - Rem básica | D8: AF01 | E8: 1020231401 | F8: Oficina sembradores | G8: PL | H8: 45961 | I8: 45961 | J8: 45964 | K8: 0000002436 | L8: 5500000425 | M8: HRPAY00001 | N8: PP0000002374 | O8: 26304.36 | P8: PEN | Q8: 26304.36 | R8: PEN | S8: 7741.13 | T8: USD
A9: 1000 | B9: 6211100001 | C9: Sueldos - Rem básica | D9: AF01 | E9: 1020230401 | F9: Mantenimiento - Jefatura | G9: PL | H9: 45961 | I9: 45961 | J9: 45964 | K9: 0000002436 | L9: 5500000425 | M9: HRPAY00001 | N9: PP0000002374 | O9: 29462.72 | P9: PEN | Q9: 29462.72 | R9: PEN | S9: 8670.61 | T9: USD
A10: 1000 | B10: 6211100001 | C10: Sueldos - Rem básica | D10: AF01 | E10: 1020231211 | F10: Ord - Zona I | G10: PL | H10: 45961 | I10: 45961 | J10: 45964 | K10: 0000002436 | L10: 5500000425 | M10: HRPAY00001 | N10: PP0000002374 | O10: 1792.75 | P10: PEN | Q10: 1792.75 | R10: PEN | S10: 527.59 | T10: USD
A11: 1000 | B11: 6211100001 | C11: Sueldos - Rem básica | D11: AF01 | E11: 1020231303 | F11: Control fitosanitario y maduración | G11: PL | H11: 45961 | I11: 45961 | J11: 45964 | K11: 0000002436 | L11: 5500000425 | M11: HRPAY00001 | N11: PP0000002374 | O11: 1887.93 | P11: PEN | Q11: 1887.93 | R11: PEN | S11: 555.6 | T11: USD
A12: 1000 | B12: 6211100001 | C12: Sueldos - Rem básica | D12: AF01 | E12: 1020231301 | F12: Oficina tecnología agrícola | G12: PL | H12: 45961 | I12: 45961 | J12: 45964 | K12: 0000002436 | L12: 5500000425 | M12: HRPAY00001 | N12: PP0000002374 | O12: 16251 | P12: PEN | Q12: 16251 | R12: PEN | S12: 4782.52 | T12: USD
A13: 1000 | B13: 6211100001 | C13: Sueldos - Rem básica | D13: AF01 | E13: 1020231214 | F13: Ord - Zona IV | G13: PL | H13: 45961 | I13: 45961 | J13: 45964 | K13: 0000002436 | L13: 5500000425 | M13: HRPAY00001 | N13: PP0000002374 | O13: 898.49 | P13: PEN | Q13: 898.49 | R13: PEN | S13: 264.42 | T13: USD
... A898: 1000 | B898: 6291100002 | C898: CTS obreros | D898: AF01 | E898: 1020230305 | F898: Aco - Patio de caña | G898: PL | H898: 45961 | I898: 45961 | J898: 45964 | K898: 0000002444 | L898: 5500000429 | M898: HRPAY00001 | N898: PP0000002382 | O898: 3798.6 | P898: PEN | Q898: 3798.6 | R898: PEN | S898: 1117.89 | T898: USD
O899: =SUM(O2:O898) -> 7446174.5 | Q899: =SUM(Q2:Q898) -> 7446174.5
A905: Sociedad | B905: Cuenta de mayor | C905: Cuenta de mayor: Texto breve | D905: Área funcional | E905: Centro de coste | F905: Centro de coste: Texto explicativo | G905: Clase de documento | H905: Fecha de documento | I905: Fe.contabilización | J905: Fecha de entrada | K905: Clave de referencia | L905: Nº documento | M905: Referencia | N905: Texto cab.documento | O905: Valor de moneda de documento | P905: Clave de moneda de documento | Q905: Valor de moneda de sociedad | R905: Clave de moneda de sociedad | S905: Valor de moneda fuerte | T905: Moneda fuerte | U905: Nombre 2 | V905: Anulado | W905: Anulado con | X905: Documento anulación
A906: 1000 | B906: 6231100004 | C906: Ind Sumas grac obrer | D906: AF01 | E906: 1020231213 | F906: Ord - Zona III | G906: PL | H906: 45961 | I906: 45961 | J906: 45960 | K906: 0000002373 | L906: 5500000400 | M906: HRPAY00001 | N906: PP0000002302 | O906: 25805 | P906: PEN | Q906: 25805 | R906: PEN | S906: 7603.12 | T906: USD

Sheet INf. RRHH
A1: Codigo | B1: Bono Cierre de Pliego | C1: Cód. CeCo | D1: Descrip. CeCo | E1: Cta.mayor | F1: Texto breve
A2: 3131 | B2: 2900 | C2: 1020231208 | D2: Ord - Man de aguas | E2: 6221100016 | F2: BonCierre pliego emp
A3: 3391 | B3: 2900 | C3: 1020231103 | D3: AD - Cultivo y fert | E3: 6221100016 | F3: BonCierre pliego emp
A4: 5581 | B4: 2900 | C4: 1020230305 | D4: Aco - Patio de caña | E4: 6221100016 | F4: BonCierre pliego emp
A5: 7018 | B5: 2900 | C5: 1020231219 | D5: OLC - Herbicidas | E5: 6221100016 | F5: BonCierre pliego emp
A6: 7106 | B6: 2900 | C6: 1020231211 | D6: Ord - Zona I | E6: 6221100016 | F6: BonCierre pliego emp
A7: 7560 | B7: 2900 | C7: 1020230304 | D7: Aco - Carg y transp | E7: 6221100016 | F7: BonCierre pliego emp
A8: 7643 | B8: 2900 | C8: 1020231401 | D8: Oficina sembradores | E8: 6221100016 | F8: BonCierre pliego emp
A9: 7901 | B9: 2900 | C9: 1020231213 | D9: Ord - Zona III | E9: 6221100016 | F9: BonCierre pliego emp
A10: 7939 | B10: 2900 | C10: 1020231214 | D10: Ord - Zona IV | E10: 6221100016 | F10: BonCierre pliego emp
A11: 8243 | B11: 2900 | C11: 1020230303 | D11: Aco - Corte de caña | E11: 6221100016 | F11: BonCierre pliego emp
A12: 9374 | B12: 2900 | C12: 1020230001 | D12: Oficina gerencia | E12: 6221100016 | F12: BonCierre pliego emp
A13: 9516 | B13: 2900 | C13: 1020230001 | D13: Oficina gerencia | E13: 6221100016 | F13: BonCierre pliego emp
... A1222: 95507 | B1222: 2900 | C1222: 1020230304 | D1222: Aco - Carg y transp | E1222: 6221100017 | F1222: BonCierre pliego obr
B1223: =SUM(B2:B1222) -> 3506100

Sheet SAP (1)
A1: Sociedad | B1: Cuenta de mayor | C1: Cuenta de mayor: Texto breve | D1: Área funcional | E1: Centro de coste | F1: Centro de coste: Texto explicativo | G1: Clase de documento | H1: Fecha de documento | I1: Fe.contabilización | J1: Fecha de entrada | K1: Clave de referencia | L1: Nº documento | M1: Referencia | N1: Texto cab.documento | O1: Valor de moneda de documento | P1: Clave de moneda de documento | Q1: Asiento | R1: Valor de moneda de documento 1 | S1: Valor de moneda de sociedad | T1: Asiento | U1: Valor de moneda de sociedad 1 | V1: Clave de moneda de sociedad | W1: Valor de moneda fuerte | X1: Moneda fuerte | Y1: Asiento | Z1: Valor de moneda fuerte 1
A2: 1000 | B2: 6211100001 | C2: Sueldos - Rem básica | D2: AF01 | E2: 1020230308 | F2: Labores de campo cosecha | G2: PL | H2: 45961 | I2: 45961 | J2: 45964 | K2: 0000002436 | L2: 5500000425 | M2: HRPAY00001 | N2: PP0000002374 | O2: 472.03 | P2: PEN | R2: =+O2+Q2 -> 472.03 | S2: 472.03 | U2: =+S2+T2 -> 472.03 | V2: PEN | W2: 138.91 | X2: USD | Z2: =+W2+Y2 -> 138.91
A3: 1000 | B3: 6211100001 | C3: Sueldos - Rem básica | D3: AF01 | E3: 1020231210 | F3: Ord - Virú | G3: PL | H3: 45961 | I3: 45961 | J3: 45964 | K3: 0000002436 | L3: 5500000425 | M3: HRPAY00001 | N3: PP0000002374 | O3: 4285.25 | P3: PEN | R3: =+O3+Q3 -> 4285.25 | S3: 4285.25 | U3: =+S3+T3 -> 4285.25 | V3: PEN | W3: 1261.11 | X3: USD | Z3: =+W3+Y3 -> 1261.11
A4: 1000 | B4: 6211100001 | C4: Sueldos - Rem básica | D4: AF01 | E4: 1020231212 | F4: Ord - Zona II | G4: PL | H4: 45961 | I4: 45961 | J4: 45964 | K4: 0000002436 | L4: 5500000425 | M4: HRPAY00001 | N4: PP0000002374 | O4: 3720.03 | P4: PEN | R4: =+O4+Q4 -> 3720.03 | S4: 3720.03 | U4: =+S4+T4 -> 3720.03 | V4: PEN | W4: 1094.77 | X4: USD | Z4: =+W4+Y4 -> 1094.77
A5: 1000 | B5: 6211100001 | C5: Sueldos - Rem básica | D5: AF01 | E5: 1020231601 | F5: Oficina control técnico agronómico | G5: PL | H5: 45961 | I5: 45961 | J5: 45964 | K5: 0000002436 | L5: 5500000425 | M5: HRPAY00001 | N5: PP0000002374 | O5: 1640 | P5: PEN | R5: =+O5+Q5 -> 1640 | S5: 1640 | U5: =+S5+T5 -> 1640 | V5: PEN | W5: 482.64 | X5: USD | Z5: =+W5+Y5 -> 482.64
A6: 1000 | B6: 6211100001 | C6: Sueldos - Rem básica | D6: AF01 | E6: 1020230303 | F6: Aco - Corte de caña | G6: PL | H6: 45961 | I6: 45961 | J6: 45964 | K6: 0000002436 | L6: 5500000425 | M6: HRPAY00001 | N6: PP0000002374 | O6: 728.66 | P6: PEN | R6: =+O6+Q6 -> 728.66 | S6: 728.66 | U6: =+S6+T6 -> 728.66 | V6: PEN | W6: 214.44 | X6: USD | Z6: =+W6+Y6 -> 214.44
A7: 1000 | B7: 6211100001 | C7: Sueldos - Rem básica | D7: AF01 | E7: 1020230301 | F7: Aco - Administración de cosecha | G7: PL | H7: 45961 | I7: 45961 | J7: 45964 | K7: 0000002436 | L7: 5500000425 | M7: HRPAY00001 | N7: PP0000002374 | O7: 18824.03 | P7: PEN | R7: =+O7+Q7 -> 18824.03 | S7: 18824.03 | U7: =+S7+T7 -> 18824.03 | V7: PEN | W7: 5539.74 | X7: USD | Z7: =+W7+Y7 -> 5539.74
A8: 1000 | B8: 6211100001 | C8: Sueldos - Rem básica | D8: AF01 | E8: 1020231401 | F8: Oficina sembradores | G8: PL | H8: 45961 | I8: 45961 | J8: 45964 | K8: 0000002436 | L8: 5500000425 | M8: HRPAY00001 | N8: PP0000002374 | O8: 26304.36 | P8: PEN | R8: =+O8+Q8 -> 26304.36 | S8: 26304.36 | U8: =+S8+T8 -> 26304.36 | V8: PEN | W8: 7741.13 | X8: USD | Z8: =+W8+Y8 -> 7741.13
A9: 1000 | B9: 6211100001 | C9: Sueldos - Rem básica | D9: AF01 | E9: 1020230401 | F9: Mantenimiento - Jefatura | G9: PL | H9: 45961 | I9: 45961 | J9: 45964 | K9: 0000002436 | L9: 5500000425 | M9: HRPAY00001 | N9: PP0000002374 | O9: 29462.72 | P9: PEN | R9: =+O9+Q9 -> 29462.72 | S9: 29462.72 | U9: =+S9+T9 -> 29462.72 | V9: PEN | W9: 8670.61 | X9: USD | Z9: =+W9+Y9 -> 8670.61
A10: 1000 | B10: 6211100001 | C10: Sueldos - Rem básica | D10: AF01 | E10: 1020231211 | F10: Ord - Zona I | G10: PL | H10: 45961 | I10: 45961 | J10: 45964 | K10: 0000002436 | L10: 5500000425 | M10: HRPAY00001 | N10: PP0000002374 | O10: 1792.75 | P10: PEN | R10: =+O10+Q10 -> 1792.75 | S10: 1792.75 | U10: =+S10+T10 -> 1792.75 | V10: PEN | W10: 527.59 | X10: USD | Z10: =+W10+Y10 -> 527.59
A11: 1000 | B11: 6211100001 | C11: Sueldos - Rem básica | D11: AF01 | E11: 1020231303 | F11: Control fitosanitario y maduración | G11: PL | H11: 45961 | I11: 45961 | J11: 45964 | K11: 0000002436 | L11: 5500000425 | M11: HRPAY00001 | N11: PP0000002374 | O11: 1887.93 | P11: PEN | R11: =+O11+Q11 -> 1887.93 | S11: 1887.93 | U11: =+S11+T11 -> 1887.93 | V11: PEN | W11: 555.6 | X11: USD | Z11: =+W11+Y11 -> 555.6
A12: 1000 | B12: 6211100001 | C12: Sueldos - Rem básica | D12: AF01 | E12: 1020231301 | F12: Oficina tecnología agrícola | G12: PL | H12: 45961 | I12: 45961 | J12: 45964 | K12: 0000002436 | L12: 5500000425 | M12: HRPAY00001 | N12: PP0000002374 | O12: 16251 | P12: PEN | R12: =+O12+Q12 -> 16251 | S12: 16251 | U12: =+S12+T12 -> 16251 | V12: PEN | W12: 4782.52 | X12: USD | Z12: =+W12+Y12 -> 4782.52
A13: 1000 | B13: 6211100001 | C13: Sueldos - Rem básica | D13: AF01 | E13: 1020231214 | F13: Ord - Zona IV | G13: PL | H13: 45961 | I13: 45961 | J13: 45964 | K13: 0000002436 | L13: 5500000425 | M13: HRPAY00001 | N13: PP0000002374 | O13: 898.49 | P13: PEN | R13: =+O13+Q13 -> 898.49 | S13: 898.49 | U13: =+S13+T13 -> 898.49 | V13: PEN | W13: 264.42 | X13: USD | Z13: =+W13+Y13 -> 264.42
... A529: 1000 | B529: 6221100015 | C529: Bonif alimentos obre | D529: AF01 | E529: 1020230305 | F529: Aco - Patio de caña | G529: PL | H529: 45961 | I529: 45961 | J529: 45964 | K529: 0000002438 | L529: 5500000426 | M529: HRPAY00001 | N529: PP0000002376 | O529: 1116 | P529: PEN | R529: =+O529+Q529 -> 1116 | S529: 1116 | U529: =+S529+T529 -> 1116 | V529: PEN | W529: 328.43 | X529: USD | Z529: =+W529+Y529 -> 328.43
A530: 1000 | B530: 6221100016 | C530: BonCierre pliego emp | D530: AF01 | E530: 1020230001 | F530: Oficina gerencia | G530: PL | H530: 45961 | I530: 45961 | J530: 45964 | K530: 0000002436 | L530: 5500000425 | M530: HRPAY00001 | N530: PP0000002374 | O530: 11600 | P530: PEN | Q530: =-ROUND(O530/3*2,2) -> -7733.33 | R530: =+O530+Q530 -> 3866.67 | S530: 11600 | T530: =+Q530 -> -7733.33 | U530: =+S530+T530 -> 3866.67 | V530: PEN | W530: 3413.77 | X530: USD | Y530: =-ROUND(W530/3*2,2) -> -2275.85 | Z530: =+W530+Y530 -> 1137.92
A531: 1000 | B531: 6221100016 | C531: BonCierre pliego emp | D531: AF01 | E531: 1020231102 | F531: Arena dulce-Infraestruc. riego por goteo | G531: PL | H531: 45961 | I531: 45961 | J531: 45964 | K531: 0000002436 | L531: 5500000425 | M531: HRPAY00001 | N531: PP0000002374 | O531: 8700 | P531: PEN | Q531: =-ROUND(O531/3*2,2) -> -5800 | R531: =+O531+Q531 -> 2900 | S531: 8700 | T531: =+Q531 -> -5800 | U531: =+S531+T531 -> 2900 | V531: PEN | W531: 2560.33 | X531: USD | Y531: =-ROUND(W531/3*2,2) -> -1706.89 | Z531: =+W531+Y531 -> 853.44
A532: 1000 | B532: 6221100016 | C532: BonCierre pliego emp | D532: AF01 | E532: 1020230303 | F532: Aco - Corte de caña | G532: PL | H532: 45961 | I532: 45961 | J532: 45964 | K532: 0000002436 | L532: 5500000425 | M532: HRPAY00001 | N532: PP0000002374 | O532: 2900 | P532: PEN | Q532: =-ROUND(O532/3*2,2) -> -1933.33 | R532: =+O532+Q532 -> 966.67 | S532: 2900 | T532: =+Q532 -> -1933.33 | U532: =+S532+T532 -> 966.67 | V532: PEN | W532: 853.44 | X532: USD | Y532: =-ROUND(W532/3*2,2) -> -568.96 | Z532: =+W532+Y532 -> 284.48
A533: 1000 | B533: 6221100016 | C533: BonCierre pliego emp | D533: AF01 | E533: 1020231216 | F533: Ord - Drenaje | G533: PL | H533: 45961 | I533: 45961 | J533: 45964 | K533: 0000002436 | L533: 5500000425 | M533: HRPAY00001 | N533: PP0000002374 | O533: 2900 | P533: PEN | Q533: =-ROUND(O533/3*2,2) -> -1933.33 | R533: =+O533+Q533 -> 966.67 | S533: 2900 | T533: =+Q533 -> -1933.33 | U533: =+S533+T533 -> 966.67 | V533: PEN | W533: 853.44 | X533: USD | Y533: =-ROUND(W533/3*2,2) -> -568.96 | Z533: =+W533+Y533 -> 284.48
A534: 1000 | B534: 6221100016 | C534: BonCierre pliego emp | D534: AF01 | E534: 1020231206 | F534: OIA - Siembra | G534: PL | H534: 45961 | I534: 45961 | J534: 45964 | K534: 0000002436 | L534: 5500000425 | M534: HRPAY00001 | N534: PP0000002374 | O534: 2900 | P534: PEN | Q534: =-ROUND(O534/3*2,2) -> -1933.33 | R534: =+O534+Q534 -> 966.67 | S534: 2900 | T534: =+Q534 -> -1933.33 | U534: =+S534+T534 -> 966.67 | V534: PEN | W534: 853.44 | X534: USD | Y534: =-ROUND(W534/3*2,2) -> -568.96 | Z534: =+W534+Y534 -> 284.48
A535: 1000 | B535: 6221100016 | C535: BonCierre pliego emp | D535: AF01 | E535: 1020231203 | F535: OIA - Ingenieria civil | G535: PL | H535: 45961 | I535: 45961 | J535: 45964 | K535: 0000002436 | L535: 5500000425 | M535: HRPAY00001 | N535: PP0000002374 | O535: 5800 | P535: PEN | Q535: =-ROUND(O535/3*2,2) -> -3866.67 | R535: =+O535+Q535 -> 1933.33 | S535: 5800 | T535: =+Q535 -> -3866.67 | U535: =+S535+T535 -> 1933.33 | V535: PEN | W535: 1706.89 | X535: USD | Y535: =-ROUND(W535/3*2,2) -> -1137.93 | Z535: =+W535+Y535 -> 568.96
A536: 1000 | B536: 6221100016 | C536: BonCierre pliego emp | D536: AF01 | E536: 1020230305 | F536: Aco - Patio de caña | G536: PL | H536: 45961 | I536: 45961 | J536: 45964 | K536: 0000002436 | L536: 5500000425 | M536: HRPAY00001 | N536: PP0000002374 | O536: 8700 | P536: PEN | Q536: =-ROUND(O536/3*2,2) -> -5800 | R536: =+O536+Q536 -> 2900 | S536: 8700 | T536: =+Q536 -> -5800 | U536: =+S536+T536 -> 2900 | V536: PEN | W536: 2560.33 | X536: USD | Y536: =-ROUND(W536/3*2,2) -> -1706.89 | Z536: =+W536+Y536 -> 853.44
A537: 1000 | B537: 6221100016 | C537: BonCierre pliego emp | D537: AF01 | E537: 1020231101 | F537: Oficina zona riego tecnificado | G537: PL | H537: 45961 | I537: 45961 | J537: 45964 | K537: 0000002436 | L537: 5500000425 | M537: HRPAY00001 | N537: PP0000002374 | O537: 2900 | P537: PEN | Q537: =-ROUND(O537/3*2,2) -> -1933.33 | R537: =+O537+Q537 -> 966.67 | S537: 2900 | T537: =+Q537 -> -1933.33 | U537: =+S537+T537 -> 966.67 | V537: PEN | W537: 853.44 | X537: USD | Y537: =-ROUND(W537/3*2,2) -> -568.96 | Z537: =+W537+Y537 -> 284.48
A538: 1000 | B538: 6221100016 | C538: BonCierre pliego emp | D538: AF01 | E538: 1020231201 | F538: Oficina zona riego por gravedad | G538: PL | H538: 45961 | I538: 45961 | J538: 45964 | K538: 0000002436 | L538: 5500000425 | M538: HRPAY00001 | N538: PP0000002374 | O538: 8700 | P538: PEN | Q538: =-ROUND(O538/3*2,2) -> -5800 | R538: =+O538+Q538 -> 2900 | S538: 8700 | T538: =+Q538 -> -5800 | U538: =+S538+T538 -> 2900 | V538: PEN | W538: 2560.33 | X538: USD | Y538: =-ROUND(W538/3*2,2) -> -1706.89 | Z538: =+W538+Y538 -> 853.44
A539: 1000 | B539: 6221100016 | C539: BonCierre pliego emp | D539: AF01 | E539: 1020231212 | F539: Ord - Zona II | G539: PL | H539: 45961 | I539: 45961 | J539: 45964 | K539: 0000002436 | L539: 5500000425 | M539: HRPAY00001 | N539: PP0000002374 | O539: 5800 | P539: PEN | Q539: =-ROUND(O539/3*2,2) -> -3866.67 | R539: =+O539+Q539 -> 1933.33 | S539: 5800 | T539: =+Q539 -> -3866.67 | U539: =+S539+T539 -> 1933.33 | V539: PEN | W539: 1706.89 | X539: USD | Y539: =-ROUND(W539/3*2,2) -> -1137.93 | Z539: =+W539+Y539 -> 568.96
A540: 1000 | B540: 6221100016 | C540: BonCierre pliego emp | D540: AF01 | E540: 1020231213 | F540: Ord - Zona III | G540: PL | H540: 45961 | I540: 45961 | J540: 45964 | K540: 0000002436 | L540: 5500000425 | M540: HRPAY00001 | N540: PP0000002374 | O540: 5800 | P540: PEN | Q540: =-ROUND(O540/3*2,2) -> -3866.67 | R540: =+O540+Q540 -> 1933.33 | S540: 5800 | T540: =+Q540 -> -3866.67 | U540: =+S540+T540 -> 1933.33 | V540: PEN | W540: 1706.89 | X540: USD | Y540: =-ROUND(W540/3*2,2) -> -1137.93 | Z540: =+W540+Y540 -> 568.96
A541: 1000 | B541: 6221100016 | C541: BonCierre pliego emp | D541: AF01 | E541: 1020230301 | F541: Aco - Administración de cosecha | G541: PL | H541: 45961 | I541: 45961 | J541: 45964 | K541: 0000002436 | L541: 5500000425 | M541: HRPAY00001 | N541: PP0000002374 | O541: 14500 | P541: PEN | Q541: =-ROUND(O541/3*2,2) -> -9666.67 | R541: =+O541+Q541 -> 4833.33 | S541: 14500 | T541: =+Q541 -> -9666.67 | U541: =+S541+T541 -> 4833.33 | V541: PEN | W541: 4267.22 | X541: USD | Y541: =-ROUND(W541/3*2,2) -> -2844.81 | Z541: =+W541+Y541 -> 1422.41
... A588: 1000 | B588: 6221100017 | C588: BonCierre pliego obr | D588: AF01 | E588: 1020231221 | F588: Proyecto piloto de ganado lechero | G588: PL | H588: 45961 | I588: 45961 | J588: 45964 | K588: 0000002438 | L588: 5500000426 | M588: HRPAY00001 | N588: PP0000002376 | O588: 63800 | P588: PEN | Q588: =-ROUND(O588/3*2,2) -> -42533.33 | R588: =+O588+Q588 -> 21266.67 | S588: 63800 | T588: =+Q588 -> -42533.33 | U588: =+S588+T588 -> 21266.67 | V588: PEN | W588: 18775.75 | X588: USD | Y588: =-ROUND(W588/3*2,2) -> -12517.17 | Z588: =+W588+Y588 -> 6258.58
A589: 1000 | B589: 6221100017 | C589: BonCierre pliego obr | D589: AF01 | E589: 1020231211 | F589: Ord - Zona I | G589: PL | H589: 45961 | I589: 45961 | J589: 45964 | K589: 0000002438 | L589: 5500000426 | M589: HRPAY00001 | N589: PP0000002376 | O589: 72500 | P589: PEN | Q589: =-ROUND(O589/3*2,2)+3.88 -> -48329.45 | R589: =+O589+Q589 -> 24170.55 | S589: 72500 | T589: =+Q589 -> -48329.45 | U589: =+S589+T589 -> 24170.55 | V589: PEN | W589: 21336.08 | X589: USD | Y589: =-ROUND(W589/3*2,2) -> -14224.05 | Z589: =+W589+Y589 -> 7112.03
A590: 1000 | B590: 6221100017 | C590: BonCierre pliego obr | D590: AF01 | E590: 1020231401 | F590: Oficina sembradores | G590: PL | H590: 45961 | I590: 45961 | J590: 45964 | K590: 0000002438 | L590: 5500000426 | M590: HRPAY00001 | N590: PP0000002376 | O590: 5800 | P590: PEN | Q590: =-ROUND(O590/3*2,2) -> -3866.67 | R590: =+O590+Q590 -> 1933.33 | S590: 5800 | T590: =+Q590 -> -3866.67 | U590: =+S590+T590 -> 1933.33 | V590: PEN | W590: 1706.89 | X590: USD | Y590: =-ROUND(W590/3*2,2) -> -1137.93 | Z590: =+W590+Y590 -> 568.96
A591: 1000 | B591: 6221100017 | C591: BonCierre pliego obr | D591: AF01 | E591: 1020230305 | F591: Aco - Patio de caña | G591: PL | H591: 45961 | I591: 45961 | J591: 45964 | K591: 0000002438 | L591: 5500000426 | M591: HRPAY00001 | N591: PP0000002376 | O591: 52200 | P591: PEN | Q591: =-ROUND(O591/3*2,2) -> -34800 | R591: =+O591+Q591 -> 17400 | S591: 52200 | T591: =+Q591 -> -34800 | U591: =+S591+T591 -> 17400 | V591: PEN | W591: 15361.98 | X591: USD | Y591: =-ROUND(W591/3*2,2) -> -10241.32 | Z591: =+W591+Y591 -> 5120.66
A592: 1000 | B592: 6221100017 | C592: BonCierre pliego obr | D592: AF01 | E592: 1020231219 | F592: OLC - Herbicidas | G592: PL | H592: 45961 | I592: 45961 | J592: 45964 | K592: 0000002438 | L592: 5500000426 | M592: HRPAY00001 | N592: PP0000002376 | O592: 258100 | P592: PEN | Q592: =-ROUND(O592/3*2,2) -> -172066.67 | R592: =+O592+Q592 -> 86033.33 | S592: 258100 | T592: =+Q592 -> -172066.67 | U592: =+S592+T592 -> 86033.33 | V592: PEN | W592: 75956.44 | X592: USD | Y592: =-ROUND(W592/3*2,2) -> -50637.63 | Z592: =+W592+Y592 -> 25318.81
A593: 1000 | B593: 6221100017 | C593: BonCierre pliego obr | D593: AF01 | E593: 1020231601 | F593: Oficina control técnico agronómico | G593: PL | H593: 45961 | I593: 45961 | J593: 45964 | K593: 0000002438 | L593: 5500000426 | M593: HRPAY00001 | N593: PP0000002376 | O593: 8700 | P593: PEN | Q593: =-ROUND(O593/3*2,2) -> -5800 | R593: =+O593+Q593 -> 2900 | S593: 8700 | T593: =+Q593 -> -5800 | U593: =+S593+T593 -> 2900 | V593: PEN | W593: 2560.33 | X593: USD | Y593: =-ROUND(W593/3*2,2) -> -1706.89 | Z593: =+W593+Y593 -> 853.44
A594: 1000 | B594: 6221100017 | C594: BonCierre pliego obr | D594: AF01 | E594: 1020231207 | F594: Oficina riego y drenaje | G594: PL | H594: 45961 | I594: 45961 | J594: 45964 | K594: 0000002438 | L594: 5500000426 | M594: HRPAY00001 | N594: PP0000002376 | O594: 17400 | P594: PEN | Q594: =-ROUND(O594/3*2,2) -> -11600 | R594: =+O594+Q594 -> 5800 | S594: 17400 | T594: =+Q594 -> -11600 | U594: =+S594+T594 -> 5800 | V594: PEN | W594: 5120.66 | X594: USD | Y594: =-ROUND(W594/3*2,2) -> -3413.77 | Z594: =+W594+Y594 -> 1706.89
A595: 1000 | B595: 6221100018 | C595: Otras remuneraciones | D595: AF01 | E595: 1020231213 | F595: Ord - Zona III | G595: PL | H595: 45961 | I595: 45961 | J595: 45964 | K595: 0000002438 | L595: 5500000426 | M595: HRPAY00001 | N595: PP0000002376 | O595: 433 | P595: PEN | R595: =+O595+Q595 -> 433 | S595: 433 | U595: =+S595+T595 -> 433 | V595: PEN | W595: 127.43 | X595: USD | Z595: =+W595+Y595 -> 127.43
A596: 1000 | B596: 6221100018 | C596: Otras remuneraciones | D596: AF01 | E596: 1020231219 | F596: OLC - Herbicidas | G596: PL | H596: 45961 | I596: 45961 | J596: 45964 | K596: 0000002438 | L596: 5500000426 | M596: HRPAY00001 | N596: PP0000002376 | O596: 4 | P596: PEN | R596: =+O596+Q596 -> 4 | S596: 4 | U596: =+S596+T596 -> 4 | V596: PEN | W596: 1.18 | X596: USD | Z596: =+W596+Y596 -> 1.18
A597: 1000 | B597: 6221100018 | C597: Otras remuneraciones | D597: AF01 | E597: 1020231212 | F597: Ord - Zona II | G597: PL | H597: 45961 | I597: 45961 | J597: 45964 | K597: 0000002438 | L597: 5500000426 | M597: HRPAY00001 | N597: PP0000002376 | O597: 187 | P597: PEN | R597: =+O597+Q597 -> 187 | S597: 187 | U597: =+S597+T597 -> 187 | V597: PEN | W597: 55.03 | X597: USD | Z597: =+W597+Y597 -> 55.03
A598: 1000 | B598: 6221100018 | C598: Otras remuneraciones | D598: AF01 | E598: 1020231211 | F598: Ord - Zona I | G598: PL | H598: 45961 | I598: 45961 | J598: 45964 | K598: 0000002438 | L598: 5500000426 | M598: HRPAY00001 | N598: PP0000002376 | O598: 223 | P598: PEN | R598: =+O598+Q598 -> 223 | S598: 223 | U598: =+S598+T598 -> 223 | V598: PEN | W598: 65.63 | X598: USD | Z598: =+W598+Y598 -> 65.63
A599: 1000 | B599: 6221100018 | C599: Otras remuneraciones | D599: AF01 | E599: 1020231214 | F599: Ord - Zona IV | G599: PL | H599: 45961 | I599: 45961 | J599: 45964 | K599: 0000002438 | L599: 5500000426 | M599: HRPAY00001 | N599: PP0000002376 | O599: 133 | P599: PEN | R599: =+O599+Q599 -> 133 | S599: 133 | U599: =+S599+T599 -> 133 | V599: PEN | W599: 39.14 | X599: USD | Z599: =+W599+Y599 -> 39.14
A600: 1000 | B600: 6221100019 | C600: Sub. econ. practi | D600: AF01 | E600: 1020230003 | F600: Analista de medio ambiente | G600: PL | H600: 45961 | I600: 45961 | J600: 45964 | K600: 0000002440 | L600: 5500000427 | M600: HRPAY00001 | N600: PP0000002378 | O600: 1112.72 | P600: PEN | R600: =+O600+Q600 -> 1112.72 | S600: 1112.72 | U600: =+S600+T600 -> 1112.72 | V600: PEN | W600: 327.46 | X600: USD | Z600: =+W600+Y600 -> 327.46
A601: 1000 | B601: 6231100006 | C601: IndPers-VacNoGoz obr | D601: AF01 | E601: 1020231103 | F601: Arena dulce - Cultivo y fertirriego | G601: PL | H601: 45961 | I601: 45961 | J601: 45964 | K601: 0000002432 | L601: 5500000423 | M601: HRPAY00001 | N601: PP0000002370 | O601: 1651.29 | P601: PEN | R601: =+O601+Q601 -> 1651.29 | S601: 1651.29 | U601: =+S601+T601 -> 1651.29 | V601: PEN | W601: 485.96 | X601: USD | Z601: =+W601+Y601 -> 485.96
...

Sheet Asiento SAP
A1: Codigo | B1: Cta. Ctble | C1: Descripción | D1: S/ | E1: $ | F1: Ce. Co. | G1: Glosa
A2: 40 | D2: =SUM(D3:D67) -> 2337396.1 | E2: =SUM(E3:E67) -> 687875.92 | G2: Dif. Bono cierre de piego 2025
A3: 50 | B3: 6221100016 | C3: BonCierre pliego emp | D3: =-'SAP (1)'!Q530 -> 7733.33 | E3: =-'SAP (1)'!Y530 -> 2275.85 | F3: 1020230001 | G3: Bono cierre pliego 2025
A4: 50 | B4: 6221100016 | C4: BonCierre pliego emp | D4: =-'SAP (1)'!Q531 -> 5800 | E4: =-'SAP (1)'!Y531 -> 1706.89 | F4: 1020231102 | G4: Bono cierre pliego 2025
A5: 50 | B5: 6221100016 | C5: BonCierre pliego emp | D5: =-'SAP (1)'!Q532 -> 1933.33 | E5: =-'SAP (1)'!Y532 -> 568.96 | F5: 1020230303 | G5: Bono cierre pliego 2025
A6: 50 | B6: 6221100016 | C6: BonCierre pliego emp | D6: =-'SAP (1)'!Q533 -> 1933.33 | E6: =-'SAP (1)'!Y533 -> 568.96 | F6: 1020231216 | G6: Bono cierre pliego 2025
A7: 50 | B7: 6221100016 | C7: BonCierre pliego emp | D7: =-'SAP (1)'!Q534 -> 1933.33 | E7: =-'SAP (1)'!Y534 -> 568.96 | F7: 1020231206 | G7: Bono cierre pliego 2025
A8: 50 | B8: 6221100016 | C8: BonCierre pliego emp | D8: =-'SAP (1)'!Q535 -> 3866.67 | E8: =-'SAP (1)'!Y535 -> 1137.93 | F8: 1020231203 | G8: Bono cierre pliego 2025
A9: 50 | B9: 6221100016 | C9: BonCierre pliego emp | D9: =-'SAP (1)'!Q536 -> 5800 | E9: =-'SAP (1)'!Y536 -> 1706.89 | F9: 1020230305 | G9: Bono cierre pliego 2025
A10: 50 | B10: 6221100016 | C10: BonCierre pliego emp | D10: =-'SAP (1)'!Q537 -> 1933.33 | E10: =-'SAP (1)'!Y537 -> 568.96 | F10: 1020231101 | G10: Bono cierre pliego 2025
A11: 50 | B11: 6221100016 | C11: BonCierre pliego emp | D11: =-'SAP (1)'!Q538 -> 5800 | E11: =-'SAP (1)'!Y538 -> 1706.89 | F11: 1020231201 | G11: Bono cierre pliego 2025
A12: 50 | B12: 6221100016 | C12: BonCierre pliego emp | D12: =-'SAP (1)'!Q539 -> 3866.67 | E12: =-'SAP (1)'!Y539 -> 1137.93 | F12: 1020231212 | G12: Bono cierre pliego 2025
A13: 50 | B13: 6221100016 | C13: BonCierre pliego emp | D13: =-'SAP (1)'!Q540 -> 3866.67 | E13: =-'SAP (1)'!Y540 -> 1137.93 | F13: 1020231213 | G13: Bono cierre pliego 2025
A14: 50 | B14: 6221100016 | C14: BonCierre pliego emp | D14: =-'SAP (1)'!Q541 -> 9666.67 | E14: =-'SAP (1)'!Y541 -> 2844.81 | F14: 1020230301 | G14: Bono cierre pliego 2025
... A67: 50 | B67: 6221100017 | C67: BonCierre pliego obr | D67: =-'SAP (1)'!Q594 -> 11600 | E67: =-'SAP (1)'!Y594 -> 3413.77 | F67: 1020231207 | G67: Bono cierre pliego 2025
