Workbook

Sheet 054M - Depreciación
A1: CD_EMPRESA_ERP | B1: CD_FILIAL_ERP | C1: DT_REFER | D1: CD_CCUSTO_ERP | E1: CD_EQUIPTO_ERP | F1: VL_TOTAL | G1: DT_ENVIO_ERP | H1: DT_INTEG_PIMS | I1: FG_STATUS_INTEG | J1: Quitar | K1: VL_TOTAL1
A2: 1000 | B2: 1000 | C2: 45961 | D2: 1020231102 | E2: 0 | F2: 225453.65 | G2: 45966 | I2: NI | J2: =ROUND(VLOOKUP(D2,SAP!$S$4:$T$18,2,0),2) -> -225.7 | K2: =+F2+J2 -> 225227.95
A3: 1000 | B3: 1000 | C3: 45961 | D3: 1020231210 | E3: 0 | F3: 34451.15 | G3: 45966 | I3: NI | J3: =ROUND(VLOOKUP(D3,SAP!$S$4:$T$18,2,0),2) -> -12274.75 | K3: =+F3+J3 -> 22176.4
A4: 1000 | B4: 1000 | C4: 45961 | D4: 1020231215 | E4: 0 | F4: 18418.56 | G4: 45966 | I4: NI | K4: =+F4+J4 -> 18418.56
A5: 1000 | B5: 1000 | C5: 45961 | D5: 1020231207 | E5: 0 | F5: 56.99 | G5: 45966 | I5: NI | K5: =+F5+J5 -> 56.99
A6: 1000 | B6: 1000 | C6: 45961 | D6: 1020231222 | E6: 3224000034 | F6: 15565.86 | G6: 45966 | I6: NI | K6: =+F6+J6 -> 15565.86
A7: 1000 | B7: 1000 | C7: 45961 | D7: 1020231209 | E7: 0 | F7: 13281.47 | G7: 45966 | I7: NI | K7: =+F7+J7 -> 13281.47
A8: 1000 | B8: 1000 | C8: 45961 | D8: 1020231213 | E8: 0 | F8: 2367.02 | G8: 45966 | I8: NI | K8: =+F8+J8 -> 2367.02
A9: 1000 | B9: 1000 | C9: 45961 | D9: 1020231102 | E9: 3331004793 | F9: 365.47 | G9: 45966 | I9: NI | K9: =+F9+J9 -> 365.47
A10: 1000 | B10: 1000 | C10: 45961 | D10: 1020230304 | E10: 3235000082 | F10: 2487.86 | G10: 45966 | I10: NI | K10: =+F10+J10 -> 2487.86
A11: 1000 | B11: 1000 | C11: 45961 | D11: 1020231210 | E11: 3341000144 | F11: 157.74 | G11: 45966 | I11: NI | K11: =+F11+J11 -> 157.74
A12: 1000 | B12: 1000 | C12: 45961 | D12: 1020231221 | E12: 3331004729 | F12: 99.57 | G12: 45966 | I12: NI | K12: =+F12+J12 -> 99.57
A13: 1000 | B13: 1000 | C13: 45961 | D13: 1020230304 | E13: 3224000020 | F13: 3487.25 | G13: 45966 | I13: NI | K13: =+F13+J13 -> 3487.25
A14: 1000 | B14: 1000 | C14: 45961 | D14: 1020231101 | E14: 0 | F14: 11661.67 | G14: 45966 | I14: NI | J14: =ROUND(VLOOKUP(D14,SAP!$S$4:$T$18,2,0),2) -> -828.16 | K14: =+F14+J14 -> 10833.51
A15: 1000 | B15: 1000 | C15: 45961 | D15: 1020230401 | E15: 0 | F15: 14562.6 | G15: 45966 | I15: NI | K15: =+F15+J15 -> 14562.6
A16: 1000 | B16: 1000 | C16: 45961 | D16: 1020231102 | E16: 3331002907 | F16: 26.66 | G16: 45966 | I16: NI | K16: =+F16+J16 -> 26.66
A17: 1000 | B17: 1000 | C17: 45961 | D17: 1020231103 | E17: 0 | F17: 696701.5 | G17: 45966 | I17: NI | J17: =ROUND(VLOOKUP(D17,SAP!$S$4:$T$18,2,0),2) -> -598839.21 | K17: =+F17+J17 -> 97862.29
A18: 1000 | B18: 1000 | C18: 45961 | D18: 1020231001 | E18: 0 | F18: 173.42 | G18: 45966 | I18: NI | K18: =+F18+J18 -> 173.42
A19: 1000 | B19: 1000 | C19: 45961 | D19: 1020231221 | E19: 0 | F19: 24101.28 | G19: 45966 | I19: NI | J19: =ROUND(VLOOKUP(D19,SAP!$S$4:$T$18,2,0),2) -> -11566.26 | K19: =+F19+J19 -> 12535.02
A20: 1000 | B20: 1000 | C20: 45961 | D20: 1020231204 | E20: 3224000075 | F20: 2966.91 | G20: 45966 | I20: NI | K20: =+F20+J20 -> 2966.91
A21: 1000 | B21: 1000 | C21: 45961 | D21: 1020231101 | E21: 3331002952 | F21: 150.81 | G21: 45966 | I21: NI | K21: =+F21+J21 -> 150.81
A22: 1000 | B22: 1000 | C22: 45961 | D22: 1020231211 | E22: 0 | F22: 2022.98 | G22: 45966 | I22: NI | K22: =+F22+J22 -> 2022.98
A23: 1000 | B23: 1000 | C23: 45961 | D23: 1020230001 | E23: 0 | F23: 14534.36 | G23: 45966 | I23: NI | K23: =+F23+J23 -> 14534.36
A24: 1000 | B24: 1000 | C24: 45961 | D24: 1020231212 | E24: 0 | F24: 2407.86 | G24: 45966 | I24: NI | K24: =+F24+J24 -> 2407.86
A25: 1000 | B25: 1000 | C25: 45961 | D25: 1020231102 | E25: 3331000028 | F25: 46.3 | G25: 45966 | I25: NI | K25: =+F25+J25 -> 46.3
A26: 1000 | B26: 1000 | C26: 45961 | D26: 1020231102 | E26: 3331000375 | F26: 59.33 | G26: 45966 | I26: NI | K26: =+F26+J26 -> 59.33
A27: 1000 | B27: 1000 | C27: 45961 | D27: 1020231105 | E27: 0 | F27: 2174.64 | G27: 45966 | I27: NI | K27: =+F27+J27 -> 2174.64
A28: 1000 | B28: 1000 | C28: 45961 | D28: 1020231103 | E28: 3224000061 | F28: 9390.8 | G28: 45966 | I28: NI | K28: =+F28+J28 -> 9390.8
A29: 1000 | B29: 1000 | C29: 45961 | D29: 1020231103 | E29: 3331004802 | F29: 472.16 | G29: 45966 | I29: NI | K29: =+F29+J29 -> 472.16
A30: 1000 | B30: 1000 | C30: 45961 | D30: 1020230301 | E30: 0 | F30: 33676.77 | G30: 45966 | I30: NI | J30: =ROUND(VLOOKUP(D30,SAP!$S$4:$T$18,2,0),2) -> -26066.88 | K30: =+F30+J30 -> 7609.89
A31: 1000 | B31: 1000 | C31: 45961 | D31: 1020230709 | E31: 3331000242 | F31: 324.64 | G31: 45966 | I31: NI | K31: =+F31+J31 -> 324.64
A32: 1000 | B32: 1000 | C32: 45961 | D32: 1020230304 | E32: 3225000014 | F32: 9159.32 | G32: 45966 | I32: NI | K32: =+F32+J32 -> 9159.32
A33: 1000 | B33: 1000 | C33: 45961 | D33: 1020231101 | E33: 3331000051 | F33: 129.26 | G33: 45966 | I33: NI | K33: =+F33+J33 -> 129.26
A34: 1000 | B34: 1000 | C34: 45961 | D34: 1020230204 | E34: 0 | F34: 216.44 | G34: 45966 | I34: NI | K34: =+F34+J34 -> 216.44
A35: 1000 | B35: 1000 | C35: 45961 | D35: 1020231303 | E35: 0 | F35: 5604.82 | G35: 45966 | I35: NI | J35: =ROUND(VLOOKUP(D35,SAP!$S$4:$T$18,2,0),2) -> -305.96 | K35: =+F35+J35 -> 5298.86
A36: 1000 | B36: 1000 | C36: 45961 | D36: 1020231222 | E36: 3331000023 | F36: 2438.25 | G36: 45966 | I36: NI | K36: =+F36+J36 -> 2438.25
A37: 1000 | B37: 1000 | C37: 45961 | D37: 1020231201 | E37: 3331004108 | F37: 320.53 | G37: 45966 | I37: NI | K37: =+F37+J37 -> 320.53
A38: 1000 | B38: 1000 | C38: 45961 | D38: 1020231201 | E38: 0 | F38: 18929.3 | G38: 45966 | I38: NI | J38: =ROUND(VLOOKUP(D38,SAP!$S$4:$T$18,2,0),2) -> -3658.19 | K38: =+F38+J38 -> 15271.11
A39: 1000 | B39: 1000 | C39: 45961 | D39: 1020230304 | E39: 3225000040 | F39: 359.64 | G39: 45966 | I39: NI | K39: =+F39+J39 -> 359.64
A40: 1000 | B40: 1000 | C40: 45961 | D40: 1020231301 | E40: 3341000050 | F40: 1973.34 | G40: 45966 | I40: NI | K40: =+F40+J40 -> 1973.34
...

Sheet SAP
H1: =+SUBTOTAL(9,H2:H63) -> -916883.88 | L1: =+SUBTOTAL(9,L2:L63) -> -97871.985
A2: Act.fijo | B2: Subnúmero | C2: Det.ctas. | D2: Nombre | E2: Nº doc. | F2: Denominación | G2: Período | H2: Impte.MS | I2: Mon.soc. | J2: ceco | K2: fecha depreciacion | L2: Mensual | M2: Quitar | N2: Codg | S2: Codg | T2: (en blanco)
A3: 3323000532 | B3: 0 | C3: A004 | D3: CONSTRUCCION DE BAÑOS - COSECHA | E3: 300000226 | F3: Amortización normal | G3: 10 | H3: -11828.41 | I3: PEN | J3: 1020230301 | K3: 45658 | L3: =+H3/10 -> -1182.841 | M3: =+H3-L3 -> -10645.569
A4: 3323000533 | B4: 0 | C4: A004 | D4: HABILITACION DE VIAS Y CONSTRUCCION DE PUENTE LARE | E4: 300000226 | F4: Amortización normal | G4: 10 | H4: -27047.43 | I4: PEN | J4: 1020230304 | K4: 45658 | L4: =+H4/10 -> -2704.743 | M4: =+H4-L4 -> -24342.687 | P4: Etiquetas de fila | Q4: Suma de Impte.MS | S4: ceco | T4: Suma de Quitar | V4: ceco | W4: Suma de Quitar
A5: 3323000534 | B5: 0 | C5: A004 | D5: RECONSTRUCCION DE VIAS ARENA DULCE | E5: 300000226 | F5: Amortización normal | G5: 10 | H5: -2395.05 | I5: PEN | J5: 1020230304 | K5: 45658 | L5: =+H5/10 -> -239.505 | M5: =+H5-L5 -> -2155.545 | P5: 1020230004 | Q5: -783.85 | S5: 1020230004 | T5: -627.08 | V5: 1020230004 | W5: -627.08 | Y5: 6841500004 | Z5: Dep equipos diversos
A6: 3323000535 | B6: 0 | C6: A004 | D6: RECONSTRUCCION DE VIAS LAREDO | E6: 300000226 | F6: Amortización normal | G6: 10 | H6: -21555.44 | I6: PEN | J6: 1020230304 | K6: 45658 | L6: =+H6/10 -> -2155.544 | M6: =+H6-L6 -> -19399.896 | P6: 1020230301 | Q6: -28963.2 | S6: 1020230301 | T6: -26066.88 | V6: 1020230301 | W6: -26066.88
A7: 3324000391 | B7: 0 | C7: A005 | D7: DOBLE MANGUERA HENRY J FILT19 - INFRAESTRUCTURA | E7: 300000227 | F7: Amortización normal | G7: 10 | H7: -18251.93 | I7: PEN | J7: 1020231103 | K7: 45658 | L7: =+H7/10 -> -1825.193 | M7: =+H7-L7 -> -16426.737 | P7: 1020230304 | Q7: -152599.86 | S7: 1020230304 | T7: -63019.791 | V7: 1020230304 | W7: -133931.23
A8: 3324000392 | B8: 0 | C8: A005 | D8: DOBLE MANGUERA CASCAJAL F1 - INFRAESTRUCTURA | E8: 300000227 | F8: Amortización normal | G8: 10 | H8: -13220.67 | I8: PEN | J8: 1020231103 | K8: 45658 | L8: =+H8/10 -> -1322.067 | M8: =+H8-L8 -> -11898.603 | P8: 1020230402 | Q8: -21183.58 | S8: 1020230402 | T8: -19065.222 | V8: 1020230402 | W8: -19065.222
A9: 3324000393 | B9: 0 | C9: A005 | D9: DOBLE MANGUERA CASCAJAL F2 - INFRAESTRUCTURA | E9: 300000227 | F9: Amortización normal | G9: 10 | H9: -17432.15 | I9: PEN | J9: 1020231103 | K9: 45658 | L9: =+H9/10 -> -1743.215 | M9: =+H9-L9 -> -15688.935 | P9: 1020231101 | Q9: -1087.55 | S9: 1020231101 | T9: -828.157 | V9: 1020231101 | W9: -828.157
A10: 3324000394 | B10: 0 | C10: A005 | D10: DOBLE MANGUERA HACIENDA REAL F8 - INFRAESTRUCTURA | E10: 300000227 | F10: Amortización normal | G10: 10 | H10: -22136.72 | I10: PEN | J10: 1020231103 | K10: 45658 | L10: =+H10/10 -> -2213.672 | M10: =+H10-L10 -> -19923.048 | P10: 1020231102 | Q10: -250.78 | S10: 1020231102 | T10: -225.702 | V10: 1020231102 | W10: -225.702
A11: 3324000395 | B11: 0 | C11: A005 | D11: DOBLE MANGUERA HACIENDA REAL F10 - INFRAESTRUCTURA | E11: 300000227 | F11: Amortización normal | G11: 10 | H11: -20509.32 | I11: PEN | J11: 1020231103 | K11: 45658 | L11: =+H11/10 -> -2050.932 | M11: =+H11-L11 -> -18458.388 | P11: 1020231103 | Q11: -666564.06 | S11: 1020231103 | T11: -598839.21 | V11: 1020231103 | W11: -598839.21
A12: 3324000396 | B12: 0 | C12: A005 | D12: DOBLE MANGUERA PALMIRA F13 - INFRAESTRUCTURA | E12: 300000227 | F12: Amortización normal | G12: 10 | H12: -17170.82 | I12: PEN | J12: 1020231103 | K12: 45658 | L12: =+H12/10 -> -1717.082 | M12: =+H12-L12 -> -15453.738 | P12: 1020231201 | Q12: -4877.59 | S12: 1020231201 | T12: -3658.19 | V12: 1020231201 | W12: -3658.19
A13: 3324000397 | B13: 0 | C13: A005 | D13: DOBLE MANGUERA DON ALBERTO F15 - INFRAESTRUCTURA | E13: 300000227 | F13: Amortización normal | G13: 10 | H13: -658.89 | I13: PEN | J13: 1020231103 | K13: 45658 | L13: =+H13/10 -> -65.889 | M13: =+H13-L13 -> -593.001 | P13: 1020231203 | Q13: -9670.5 | S13: 1020231203 | T13: -8596 | V13: 1020231203 | W13: -8596
A14: 3324000398 | B14: 0 | C14: A005 | D14: DOBLE MANGUERA DON ALBERTO F16 - INFRAESTRUCTURA | E14: 300000227 | F14: Amortización normal | G14: 10 | H14: -16649.66 | I14: PEN | J14: 1020231103 | K14: 45658 | L14: =+H14/10 -> -1664.966 | M14: =+H14-L14 -> -14984.694 | P14: 1020231210 | Q14: -13638.61 | S14: 1020231210 | T14: -12274.749 | V14: 1020231210 | W14: -12274.749
A15: 3324000399 | B15: 0 | C15: A005 | D15: DOBLE MANGUERA DON ALBERTO F17 - INFRAESTRUCTURA | E15: 300000227 | F15: Amortización normal | G15: 10 | H15: -19250.76 | I15: PEN | J15: 1020231103 | K15: 45658 | L15: =+H15/10 -> -1925.076 | M15: =+H15-L15 -> -17325.684 | P15: 1020231221 | Q15: -13501.68 | S15: 1020231221 | T15: -11566.26 | V15: 1020231221 | W15: -11566.26
A16: 3324000400 | B16: 0 | C16: A005 | D16: DOBLE MANGUERA HENRY J F20 - INFRAESTRUCTURA | E16: 300000227 | F16: Amortización normal | G16: 10 | H16: -10557.88 | I16: PEN | J16: 1020231103 | K16: 45658 | L16: =+H16/10 -> -1055.788 | M16: =+H16-L16 -> -9502.092 | P16: 1020231303 | Q16: -356.96 | S16: 1020231303 | T16: -305.96 | V16: 1020231303 | W16: -305.96
A17: 3324000401 | B17: 0 | C17: A005 | D17: DOBLE MANGUERA HENRY J F21 - INFRAESTRUCTURA | E17: 300000227 | F17: Amortización normal | G17: 10 | H17: -1848.94 | I17: PEN | J17: 1020231103 | K17: 45658 | L17: =+H17/10 -> -184.894 | M17: =+H17-L17 -> -1664.046 | P17: 1020231304 | Q17: -3405.66 | S17: 1020231304 | T17: -3027.26 | V17: 1020231304 | W17: -3027.26
A18: 3324000402 | B18: 0 | C18: A005 | D18: DOBLE MANGUERA HENRY J F22 - INFRAESTRUCTURA | E18: 300000227 | F18: Amortización normal | G18: 10 | H18: -6407.9 | I18: PEN | J18: 1020231103 | K18: 45658 | L18: =+H18/10 -> -640.79 | M18: =+H18-L18 -> -5767.11 | P18: Total general | Q18: -916883.88 | S18: Total general | T18: -748100.46 | V18: Total general | W18: -819011.89
A19: 3324000403 | B19: 0 | C19: A005 | D19: POZO TUBULAR NUEVO CAMPO ESPINAL JR 2 CTL 5 | E19: 300000227 | F19: Amortización normal | G19: 10 | H19: -4043.21 | I19: PEN | J19: 1020231210 | K19: 45658 | L19: =+H19/10 -> -404.321 | M19: =+H19-L19 -> -3638.889
A20: 3324000404 | B20: 0 | C20: A005 | D20: CONSTRUCCION TORRE VENTADA 9M | E20: 300000227 | F20: Amortización normal | G20: 10 | H20: -387.05 | I20: PEN | J20: 1020231103 | K20: 45901 | L20: -193.52 | M20: =+H20-L20 -> -193.53
A21: 3324000405 | B21: 0 | C21: A005 | D21: ADECUACION Y HABILITACIÓN DE NUEVAS VIAS ARENA DUL | E21: 300000227 | F21: Amortización normal | G21: 10 | H21: -278.31 | I21: PEN | J21: 1020231103 | K21: 45658 | L21: =+H21/10 -> -27.831 | M21: =+H21-L21 -> -250.479 | S21: Codg | T21: 1
A22: 3324000406 | B22: 0 | C22: A005 | D22: HABILITACION DE VIAS CAMPO ARENA DULCE | E22: 300000227 | F22: Amortización normal | G22: 10 | H22: -3311.53 | I22: PEN | J22: 1020230304 | K22: 45658 | L22: =+H22/10 -> -331.153 | M22: =+H22-L22 -> -2980.377
A23: 3324000407 | B23: 0 | C23: A005 | D23: HABILITACION DE VIAS CAMPO CORTIJO | E23: 300000227 | F23: Amortización normal | G23: 10 | H23: -567.77 | I23: PEN | J23: 1020230304 | K23: 45658 | L23: =+H23/10 -> -56.777 | M23: =+H23-L23 -> -510.993 | S23: Act.fijo | T23: Suma de Quitar
A24: 3324000408 | B24: 0 | C24: A005 | D24: HABILITACION DE VIAS CAMPO VIRU | E24: 300000227 | F24: Amortización normal | G24: 10 | H24: -851.55 | I24: PEN | J24: 1020230304 | K24: 45658 | L24: =+H24/10 -> -85.155 | M24: =+H24-L24 -> -766.395 | S24: 3331004825 | T24: -17043.26
A25: 3331004812 | B25: 0 | C25: A006 | D25: DOBLE MANGUERA HENRY J F19 - MANGUERA | E25: 300000233 | F25: Amortización normal | G25: 10 | H25: -43594.31 | I25: PEN | J25: 1020231103 | K25: 45658 | L25: =+H25/10 -> -4359.431 | M25: =+H25-L25 -> -39234.879 | S25: 3331004826 | T25: -2204.82
A26: 3331004813 | B26: 0 | C26: A006 | D26: DOBLE MANGUERA CASCAJAL J F1 - MANGUERA | E26: 300000233 | F26: Amortización normal | G26: 10 | H26: -11168.27 | I26: PEN | J26: 1020231103 | K26: 45658 | L26: =+H26/10 -> -1116.827 | M26: =+H26-L26 -> -10051.443 | S26: 3331004827 | T26: -51663.357
A27: 3331004814 | B27: 0 | C27: A006 | D27: DOBLE MANGUERA CASCAJAL J F2 - MANGUERA | E27: 300000233 | F27: Amortización normal | G27: 10 | H27: -57050.83 | I27: PEN | J27: 1020231103 | K27: 45658 | L27: =+H27/10 -> -5705.083 | M27: =+H27-L27 -> -51345.747 | S27: Total general | T27: -70911.437
A28: 3331004815 | B28: 0 | C28: A006 | D28: DOBLE MANGUERA HACIENDA REAL F8 - MANGUERA | E28: 300000233 | F28: Amortización normal | G28: 10 | H28: -61644.76 | I28: PEN | J28: 1020231103 | K28: 45658 | L28: =+H28/10 -> -6164.476 | M28: =+H28-L28 -> -55480.284
A29: 3331004816 | B29: 0 | C29: A006 | D29: DOBLE MANGUERA HACIENDA REAL F10 - MANGUERA | E29: 300000233 | F29: Amortización normal | G29: 10 | H29: -74028.63 | I29: PEN | J29: 1020231103 | K29: 45658 | L29: =+H29/10 -> -7402.863 | M29: =+H29-L29 -> -66625.767
A30: 3331004817 | B30: 0 | C30: A006 | D30: DOBLE MANGUERA PALMIRA F13 - MANGUERA | E30: 300000233 | F30: Amortización normal | G30: 10 | H30: -64228.75 | I30: PEN | J30: 1020231103 | K30: 45658 | L30: =+H30/10 -> -6422.875 | M30: =+H30-L30 -> -57805.875 | P30: Etiquetas de fila
A31: 3331004818 | B31: 0 | C31: A006 | D31: DOBLE MANGUERA DON ALBERTO F15 - MANGUERA | E31: 300000233 | F31: Amortización normal | G31: 10 | H31: -1711.94 | I31: PEN | J31: 1020231103 | K31: 45658 | L31: =+H31/10 -> -171.194 | M31: =+H31-L31 -> -1540.746 | P31: 6841100003 | Q31: DepEdific producción | S31: 6841100005 | T31: DepEdific producción M | V31: 3952100004 | W31: Depreciación edificaciones para producción M
A32: 3331004819 | B32: 0 | C32: A006 | D32: DOBLE MANGUERA DON ALBERTO F16 - MANGUERA | E32: 300000233 | F32: Amortización normal | G32: 10 | H32: -55277.58 | I32: PEN | J32: 1020231103 | K32: 45658 | L32: =+H32/10 -> -5527.758 | M32: =+H32-L32 -> -49749.822 | P32: 6841100004 | Q32: DeprEdific instalac | S32: 6841100006 | T32: DeprEdific instalac M | V32: 3952200002 | W32: Depreciación edificaciones instalaciones M
A33: 3331004820 | B33: 0 | C33: A006 | D33: DOBLE MANGUERA DON ALBERTO F17 - MANGUERA | E33: 300000233 | F33: Amortización normal | G33: 10 | H33: -65587.95 | I33: PEN | J33: 1020231103 | K33: 45658 | L33: =+H33/10 -> -6558.795 | M33: =+H33-L33 -> -59029.155 | P33: 6841200001 | Q33: DepMaq. EquipExplot | S33: 6841200002 | T33: DepMaq. EquipExplot M | V33: 3952400002 | W33: Depre. maquinaria y equipos de explotación M
A34: 3331004821 | B34: 0 | C34: A006 | D34: DOBLE MANGUERA HENRY J F20 - MANGUERA | E34: 300000233 | F34: Amortización normal | G34: 10 | H34: -45444.92 | I34: PEN | J34: 1020231103 | K34: 45658 | L34: =+H34/10 -> -4544.492 | M34: =+H34-L34 -> -40900.428 | P34: 6841500004 | Q34: Dep equipos diversos | S34: 6841500005 | T34: Dep equipos diversos M | V34: 3952700005 | W34: Depreciación equipos diversos M
A35: 3331004822 | B35: 0 | C35: A006 | D35: DOBLE MANGUERA HENRY J F21 - MANGUERA | E35: 300000233 | F35: Amortización normal | G35: 10 | H35: -6511.06 | I35: PEN | J35: 1020231103 | K35: 45658 | L35: =+H35/10 -> -651.106 | M35: =+H35-L35 -> -5859.954 | P35: 6861900001 | Q35: Amort otros act inta | S35: 6861900002 | T35: Amort otros act inta M | V35: 3961900002 | W35: Amortización otros activos intangibles - Costo M
A36: 3331004823 | B36: 0 | C36: A006 | D36: DOBLE MANGUERA HENRY J F22 - MANGUERA | E36: 300000233 | F36: Amortización normal | G36: 10 | H36: -6293.38 | I36: PEN | J36: 1020231103 | K36: 45658 | L36: =+H36/10 -> -629.338 | M36: =+H36-L36 -> -5664.042 | P36: Total general
A37: 3331004824 | B37: 0 | C37: A006 | D37: TRANSFORMADOR GyR ELECTRIC | E37: 300000233 | F37: Amortización normal | G37: 10 | H37: -356.96 | I37: PEN | J37: 1020231303 | K37: 45748 | L37: -51 | M37: =+H37-L37 -> -305.96
A38: 3331004825 | B38: 0 | C38: A006 | D38: OVERHAUL COSECHADORA ORUGA JHON DEERE | E38: 300000233 | F38: Amortización normal | G38: 10 | H38: -22724.34 | I38: PEN | J38: 1020230304 | K38: 45839 | L38: -5681.08 | M38: =+H38-L38 -> -17043.26 | N38: 1 | O38: 3224000003
A39: 3331004826 | B39: 0 | C39: A006 | D39: OVERHAUL COSECHADORA DE CAÑA JOHN DEERE CH570 | E39: 300000233 | F39: Amortización normal | G39: 10 | H39: -2449.8 | I39: PEN | J39: 1020230304 | K39: 45658 | L39: =+H39/10 -> -244.98 | M39: =+H39-L39 -> -2204.82 | N39: 1 | O39: 3331000009
A40: 3331004827 | B40: 0 | C40: A006 | D40: OVERHAUL COSECHADORA JOHN DEERE | E40: 300000233 | F40: Amortización normal | G40: 10 | H40: -57403.73 | I40: PEN | J40: 1020230304 | K40: 45658 | L40: =+H40/10 -> -5740.373 | M40: =+H40-L40 -> -51663.357 | N40: 1 | O40: 3224000002
...
